Workbook

Sheet swiss_qna
A2: Staatssekretariat für Wirtschaft SECO
A3: Secrétariat d'Etat à l'économie SECO
A4: Segreteria di Stato dell’economia SECO
A5: Secretariat da stadi per l'economia SECO
A6: State Secretariat for Economic Affairs SECO
A8: You may choose the language to label the Swiss GDP and its expenditure components in the dropdown-menu below.
A9: Pages labelled at the end with "_q" contain quarterly data, pages with "_y" contain yearly figures.
A10: Pages labelled at the beginning with "nom" contain figures at current prices, pages with "real" contain values at prices of the preceding year (chained values, reference year 2015), pages with "defl" contain implicit price deflators and those with "gc" contain contributions to real GDP-growth.
A12: Sie können im Dropdown-Menu die Sprache wählen, im welcher Sie das BIP der Schweiz gemäss Verwendungsseite beschriftet haben möchten.
A13: Seiten mit der Endbezeichnung "_q" enthalten Quartalszahlen, diejenigen mit "_y" Jahreszahlen.
A14: Seiten mit der Anfangsbezeichnung "nom" enthalten Werte zu laufenden Preisen, diejenigen mit "real" Werte zu Preisen des Vorjahres (verkettet, Referenzjahr 2015), diejenigen mit "defl" implizite Deflatoren und diejenigen mit "gc" Beiträge zum realen BIP-Wachstum.
A16: Vous pouvez choisir ci-dessous la langue avec laquelle vous souhaitez visualiser le PIB de la Suisse selon l'approche par la dépense.
... A22: Le pagine contrassegnate all'inizio con "nom" contengono dati ai prezzi correnti, pagine con "real" contengono valori ai prezzi dell'anno precedente (serie concatenate, anno di riferimento 2015), pagine con "defl" contengono i deflatori impliciti, pagine con "gc" contengono i contributi alla crescita reale del PIL.

Sheet nom_q
A1: =IF(INDIRECT("beschriftung!"&ADDRESS(beschriftung!$C$1*12+ROW(beschriftung!$A1)-1,COLUMN(beschriftung!A$1)))="","",INDIRECT("beschriftung!"&ADDRESS(beschriftung!$C$1*12+ROW(beschriftung!$A1)-1,COLUMN(beschriftung!A$1)))) -> ESA 2010, Quarterly aggregates of Gross Domestic Product, expenditure approach, seasonally, calendar and sport event adjusted data. Background information on sport event adjustment can be found in the publication “Konjunkturtendenzen” (“Economic Trends”) from autumn 2022 and in the technical note from 5 September 2022 on the website www.seco.admin.ch.
A2: =IF(INDIRECT("beschriftung!"&ADDRESS(beschriftung!$C$1*12+ROW(beschriftung!$A2)-1,COLUMN(beschriftung!A$1)))="","",INDIRECT("beschriftung!"&ADDRESS(beschriftung!$C$1*12+ROW(beschriftung!$A2)-1,COLUMN(beschriftung!A$1)))) -> In Mio. Swiss Francs, at current prices, percentage change to previous quarter
A3: =IF(INDIRECT("beschriftung!"&ADDRESS(beschriftung!$C$1*12+ROW(beschriftung!$A5)-1,COLUMN(beschriftung!A$1)))="","",INDIRECT("beschriftung!"&ADDRESS(beschriftung!$C$1*12+ROW(beschriftung!$A5)-1,COLUMN(beschriftung!A$1))))
C4: =IF(INDIRECT("beschriftung!"&ADDRESS(beschriftung!$C$1*12+ROW(beschriftung!$A5)-1,COLUMN(beschriftung!C$1)))="","",INDIRECT("beschriftung!"&ADDRESS(beschriftung!$C$1*12+ROW(beschriftung!$A5)-1,COLUMN(beschriftung!C$1)))) -> Gross domestic product
E5: =IF(INDIRECT("beschriftung!"&ADDRESS(beschriftung!$C$1*12+ROW(beschriftung!$A6)-1,COLUMN(beschriftung!E$1)))="","",INDIRECT("beschriftung!"&ADDRESS(beschriftung!$C$1*12+ROW(beschriftung!$A6)-1,COLUMN(beschriftung!E$1)))) -> Internal demand | Y5: =IF(INDIRECT("beschriftung!"&ADDRESS(beschriftung!$C$1*12+ROW(beschriftung!$A6)-1,COLUMN(beschriftung!Y$1)))="","",INDIRECT("beschriftung!"&ADDRESS(beschriftung!$C$1*12+ROW(beschriftung!$A6)-1,COLUMN(beschriftung!Y$1)))) -> Trade balance (goods and services) | AU5: =IF(INDIRECT("beschriftung!"&ADDRESS(beschriftung!$C$1*12+ROW(beschriftung!$A6)-1,COLUMN(beschriftung!AU$1)))="","",INDIRECT("beschriftung!"&ADDRESS(beschriftung!$C$1*12+ROW(beschriftung!$A6)-1,COLUMN(beschriftung!AU$1)))) -> Global demand excluding inventories change, stat. discrepancies and valuables
G6: =IF(INDIRECT("beschriftung!"&ADDRESS(beschriftung!$C$1*12+ROW(beschriftung!$A7)-1,COLUMN(beschriftung!G$1)))="","",INDIRECT("beschriftung!"&ADDRESS(beschriftung!$C$1*12+ROW(beschriftung!$A7)-1,COLUMN(beschriftung!G$1)))) -> Final consumption expenditure | M6: =IF(INDIRECT("beschriftung!"&ADDRESS(beschriftung!$C$1*12+ROW(beschriftung!$A7)-1,COLUMN(beschriftung!M$1)))="","",INDIRECT("beschriftung!"&ADDRESS(beschriftung!$C$1*12+ROW(beschriftung!$A7)-1,COLUMN(beschriftung!M$1)))) -> Gross capital formation | AA6: =IF(INDIRECT("beschriftung!"&ADDRESS(beschriftung!$C$1*12+ROW(beschriftung!$A7)-1,COLUMN(beschriftung!AA$1)))="","",INDIRECT("beschriftung!"&ADDRESS(beschriftung!$C$1*12+ROW(beschriftung!$A7)-1,COLUMN(beschriftung!AA$1)))) -> Exports of goods and services | AK6: =IF(INDIRECT("beschriftung!"&ADDRESS(beschriftung!$C$1*12+ROW(beschriftung!$A7)-1,COLUMN(beschriftung!AK$1)))="","",INDIRECT("beschriftung!"&ADDRESS(beschriftung!$C$1*12+ROW(beschriftung!$A7)-1,COLUMN(beschriftung!AK$1)))) -> Imports of goods and services | AW6: =IF(INDIRECT("beschriftung!"&ADDRESS(beschriftung!$C$1*12+ROW(beschriftung!$A7)-1,COLUMN(beschriftung!AW$1)))="","",INDIRECT("beschriftung!"&ADDRESS(beschriftung!$C$1*12+ROW(beschriftung!$A7)-1,COLUMN(beschriftung!AW$1)))) -> Final domestic demand | AY6: =IF(INDIRECT("beschriftung!"&ADDRESS(beschriftung!$C$1*12+ROW(beschriftung!$A7)-1,COLUMN(beschriftung!AY$1)))="","",INDIRECT("beschriftung!"&ADDRESS(beschriftung!$C$1*12+ROW(beschriftung!$A7)-1,COLUMN(beschriftung!AY$1)))) -> Exports of goods and services (excluding valuables) | BC6: =IF(INDIRECT("beschriftung!"&ADDRESS(beschriftung!$C$1*12+ROW(beschriftung!$A7)-1,COLUMN(beschriftung!BC$1)))="","",INDIRECT("beschriftung!"&ADDRESS(beschriftung!$C$1*12+ROW(beschriftung!$A7)-1,COLUMN(beschriftung!BC$1)))) -> Imports of goods and services (excluding valuables)
I7: =IF(INDIRECT("beschriftung!"&ADDRESS(beschriftung!$C$1*12+ROW(beschriftung!$A8)-1,COLUMN(beschriftung!I$1)))="","",INDIRECT("beschriftung!"&ADDRESS(beschriftung!$C$1*12+ROW(beschriftung!$A8)-1,COLUMN(beschriftung!I$1)))) -> Households and NPISH | K7: =IF(INDIRECT("beschriftung!"&ADDRESS(beschriftung!$C$1*12+ROW(beschriftung!$A8)-1,COLUMN(beschriftung!K$1)))="","",INDIRECT("beschriftung!"&ADDRESS(beschriftung!$C$1*12+ROW(beschriftung!$A8)-1,COLUMN(beschriftung!K$1)))) -> General government | O7: =IF(INDIRECT("beschriftung!"&ADDRESS(beschriftung!$C$1*12+ROW(beschriftung!$A8)-1,COLUMN(beschriftung!O$1)))="","",INDIRECT("beschriftung!"&ADDRESS(beschriftung!$C$1*12+ROW(beschriftung!$A8)-1,COLUMN(beschriftung!O$1)))) -> Gross fixed capital formation | U7: =IF(INDIRECT("beschriftung!"&ADDRESS(beschriftung!$C$1*12+ROW(beschriftung!$A8)-1,COLUMN(beschriftung!U$1)))="","",INDIRECT("beschriftung!"&ADDRESS(beschriftung!$C$1*12+ROW(beschriftung!$A8)-1,COLUMN(beschriftung!U$1)))) -> Changes in inventories and statistical discrepancies | W7: =IF(INDIRECT("beschriftung!"&ADDRESS(beschriftung!$C$1*12+ROW(beschriftung!$A8)-1,COLUMN(beschriftung!W$1)))="","",INDIRECT("beschriftung!"&ADDRESS(beschriftung!$C$1*12+ROW(beschriftung!$A8)-1,COLUMN(beschriftung!W$1)))) -> Acquisitions less disposals of valuables | AC7: =IF(INDIRECT("beschriftung!"&ADDRESS(beschriftung!$C$1*12+ROW(beschriftung!$A8)-1,COLUMN(beschriftung!AC$1)))="","",INDIRECT("beschriftung!"&ADDRESS(beschriftung!$C$1*12+ROW(beschriftung!$A8)-1,COLUMN(beschriftung!AC$1)))) -> Exports (exp.) of goods | AI7: =IF(INDIRECT("beschriftung!"&ADDRESS(beschriftung!$C$1*12+ROW(beschriftung!$A8)-1,COLUMN(beschriftung!AI$1)))="","",INDIRECT("beschriftung!"&ADDRESS(beschriftung!$C$1*12+ROW(beschriftung!$A8)-1,COLUMN(beschriftung!AI$1)))) -> Exports of services | AM7: =IF(INDIRECT("beschriftung!"&ADDRESS(beschriftung!$C$1*12+ROW(beschriftung!$A8)-1,COLUMN(beschriftung!AM$1)))="","",INDIRECT("beschriftung!"&ADDRESS(beschriftung!$C$1*12+ROW(beschriftung!$A8)-1,COLUMN(beschriftung!AM$1)))) -> Imports (imp.) of goods | AS7: =IF(INDIRECT("beschriftung!"&ADDRESS(beschriftung!$C$1*12+ROW(beschriftung!$A8)-1,COLUMN(beschriftung!AS$1)))="","",INDIRECT("beschriftung!"&ADDRESS(beschriftung!$C$1*12+ROW(beschriftung!$A8)-1,COLUMN(beschriftung!AS$1)))) -> Imports of services | BA7: =IF(INDIRECT("beschriftung!"&ADDRESS(beschriftung!$C$1*12+ROW(beschriftung!$A8)-1,COLUMN(beschriftung!BA$1)))="","",INDIRECT("beschriftung!"&ADDRESS(beschriftung!$C$1*12+ROW(beschriftung!$A8)-1,COLUMN(beschriftung!BA$1)))) -> thereof exports of goods excluding valuables
Q8: =IF(INDIRECT("beschriftung!"&ADDRESS(beschriftung!$C$1*12+ROW(beschriftung!$A9)-1,COLUMN(beschriftung!Q$1)))="","",INDIRECT("beschriftung!"&ADDRESS(beschriftung!$C$1*12+ROW(beschriftung!$A9)-1,COLUMN(beschriftung!Q$1)))) -> Construction | S8: =IF(INDIRECT("beschriftung!"&ADDRESS(beschriftung!$C$1*12+ROW(beschriftung!$A9)-1,COLUMN(beschriftung!S$1)))="","",INDIRECT("beschriftung!"&ADDRESS(beschriftung!$C$1*12+ROW(beschriftung!$A9)-1,COLUMN(beschriftung!S$1)))) -> Fixed assets and software | AE8: =IF(INDIRECT("beschriftung!"&ADDRESS(beschriftung!$C$1*12+ROW(beschriftung!$A9)-1,COLUMN(beschriftung!AE$1)))="","",INDIRECT("beschriftung!"&ADDRESS(beschriftung!$C$1*12+ROW(beschriftung!$A9)-1,COLUMN(beschriftung!AE$1)))) -> thereof exp. of goods excluding non-monetary gold | AG8: =IF(INDIRECT("beschriftung!"&ADDRESS(beschriftung!$C$1*12+ROW(beschriftung!$A9)-1,COLUMN(beschriftung!AG$1)))="","",INDIRECT("beschriftung!"&ADDRESS(beschriftung!$C$1*12+ROW(beschriftung!$A9)-1,COLUMN(beschriftung!AG$1)))) -> thereof exp. of goods excluding valuables and merchanting | AO8: =IF(INDIRECT("beschriftung!"&ADDRESS(beschriftung!$C$1*12+ROW(beschriftung!$A9)-1,COLUMN(beschriftung!AO$1)))="","",INDIRECT("beschriftung!"&ADDRESS(beschriftung!$C$1*12+ROW(beschriftung!$A9)-1,COLUMN(beschriftung!AO$1)))) -> thereof imp. of goods excluding non-monetary gold | AQ8: =IF(INDIRECT("beschriftung!"&ADDRESS(beschriftung!$C$1*12+ROW(beschriftung!$A9)-1,COLUMN(beschriftung!AQ$1)))="","",INDIRECT("beschriftung!"&ADDRESS(beschriftung!$C$1*12+ROW(beschriftung!$A9)-1,COLUMN(beschriftung!AQ$1)))) -> thereof imp. of goods excluding valuables
C11: B.1*b | E11: P.3+P.5 | G11: P.3 | I11: S.14+S15 | K11: S.13 | M11: P.5 | O11: P.51 | Q11: P.5111c | S11: P.5111be | U11: P.52 | W11: P.53 | AA11: P.6 | AC11: P.61 | AI11: P.62 | AK11: P.7 | AM11: P.71 | AS11: P.72 | AW11: P.3+P.51
A12: 1980 | B12: 1 | C12: 50219.523 | E12: 53790.619 | G12: 34282.617 | I12: 29603.005 | K12: 4679.6116 | M12: 19508.002 | O12: 15383.762 | Q12: 6084.2698 | S12: 9299.4919 | U12: 1710.0567 | W12: 2414.1836 | Y12: -3571.0961 | AA12: 22972.912 | AC12: 17395.752 | AE12: 12310.211 | AG12: 10957.194 | AI12: 5577.1601 | AK12: 26544.008 | AM12: 22487.765 | AO12: 15428.234 | AQ12: 13806.995 | AS12: 4056.243 | AU12: 66372.704 | AW12: 49666.379 | AY12: 16706.325 | BA12: 11129.165 | BC12: 17863.238
A13: 1980 | B13: 2 | C13: 50869.75 | D13: 0.0129477 | E13: 51784.139 | F13: -0.037301683 | G13: 34662.214 | H13: 0.01107259 | I13: 29857.971 | J13: 0.0086128141 | K13: 4804.2438 | L13: 0.026633019 | M13: 17121.924 | N13: -0.12231278 | O13: 15416.203 | P13: 0.0021087834 | Q13: 6406.2668 | R13: 0.052922865 | S13: 9009.9359 | T13: -0.031136752 | U13: 1463.5709 | W13: 242.15043 | Y13: -914.38821 | AA13: 23078.424 | AB13: 0.0045928857 | AC13: 17347.62 | AD13: -0.0027668998 | AE13: 12349.936 | AF13: 0.0032270319 | AG13: 11090.722 | AH13: 0.01218636 | AI13: 5730.8043 | AJ13: 0.027548834 | AK13: 23992.812 | AL13: -0.096111934 | AM13: 19867.366 | AN13: -0.11652553 | AO13: 14842.82 | AP13: -0.037944339 | AQ13: 13544.076 | AR13: -0.0190424 | AS13: 4125.4457 | AT13: 0.01706079 | AU13: 67075.701 | AV13: 0.010591665 | AW13: 50078.417 | AX13: 0.008296123 | AY13: 16997.284 | AZ13: 0.017416103 | BA13: 11266.48 | BB13: 0.012338286 | BC13: 17669.522 | BD13: -0.010844373
A14: 1980 | B14: 3 | C14: 51636.923 | D14: 0.015081111 | E14: 51774.869 | F14: -0.00017900004 | G14: 35146.872 | H14: 0.013982308 | I14: 30245.028 | J14: 0.01296327 | K14: 4901.8446 | L14: 0.020315541 | M14: 16627.997 | N14: -0.028847641 | O14: 15769.262 | P14: 0.022901847 | Q14: 6679.2947 | R14: 0.042618867 | S14: 9089.9676 | T14: 0.0088826032 | U14: 1745.3998 | W14: -886.66509 | Y14: -137.94649 | AA14: 24165.838 | AB14: 0.047118204 | AC14: 18271.626 | AD14: 0.053264188 | AE14: 12391.699 | AF14: 0.003381621 | AG14: 11212.342 | AH14: 0.010965903 | AI14: 5894.2114 | AJ14: 0.028513804 | AK14: 24303.784 | AL14: 0.012961056 | AM14: 20078.533 | AN14: 0.010628832 | AO14: 15229.718 | AP14: 0.026066397 | AQ14: 14090.948 | AR14: 0.040377203 | AS14: 4225.251 | AT14: 0.024192602 | AU14: 68207.722 | AV14: 0.016876762 | AW14: 50916.134 | AX14: 0.01672811 | AY14: 17291.588 | AZ14: 0.01731473 | BA14: 11397.376 | BB14: 0.011618212 | BC14: 18316.199 | BD14: 0.036598454
A15: 1980 | B15: 4 | C15: 52490.256 | D15: 0.016525649 | E15: 52514.094 | F15: 0.014277673 | G15: 35622.311 | H15: 0.013527192 | I15: 30629.542 | J15: 0.012713326 | K15: 4992.7682 | L15: 0.018548857 | M15: 16891.783 | N15: 0.015863976 | O15: 16237.238 | P15: 0.029676448 | Q15: 6954.4241 | R15: 0.041191383 | S15: 9282.8139 | T15: 0.02121529 | U15: 1355.5279 | W15: -700.98274 | Y15: -23.837488 | AA15: 24895.291 | AB15: 0.030185325 | AC15: 18828.656 | AD15: 0.03048606 | AE15: 12864.208 | AF15: 0.038131037 | AG15: 11415.522 | AH15: 0.018121121 | AI15: 6066.6351 | AJ15: 0.029253069 | AK15: 24919.129 | AL15: 0.025318883 | AM15: 20578.796 | AN15: 0.024915311 | AO15: 15284.69 | AP15: 0.0036095202 | AQ15: 14065.294 | AR15: -0.0018206342 | AS15: 4340.3327 | AT15: 0.027236668 | AU15: 69540.355 | AV15: 0.019537859 | AW15: 51859.549 | AX15: 0.018528786 | AY15: 17680.806 | AZ15: 0.022509133 | BA15: 11614.171 | BB15: 0.019021472 | BC15: 18405.626 | BD15: 0.0048824155
A16: 1981 | B16: 1 | C16: 53212.598 | D16: 0.013761438 | E16: 53108.093 | F16: 0.011311232 | G16: 36349.388 | H16: 0.020410717 | I16: 31241.365 | J16: 0.019974921 | K16: 5108.0225 | L16: 0.02308423 | M16: 16758.705 | N16: -0.0078782549 | O16: 16563.294 | P16: 0.020080771 | Q16: 7156.8406 | R16: 0.02910615 | S16: 9406.4536 | T16: 0.01331921 | U16: 949.85754 | W16: -754.44641 | Y16: 104.50479 | AA16: 25501.468 | AB16: 0.02434905 | AC16: 19334.627 | AD16: 0.026872362 | AE16: 13206.496 | AF16: 0.026607834 | AG16: 11782.755 | AH16: 0.032169619 | AI16: 6166.8413 | AJ16: 0.016517594 | AK16: 25396.963 | AL16: 0.019175406 | AM16: 20917.586 | AN16: 0.016463066 | AO16: 15194.691 | AP16: -0.005888217 | AQ16: 14332.264 | AR16: 0.018980772 | AS16: 4479.377 | AT16: 0.032035407 | AU16: 71074.381 | AV16: 0.022059511 | AW16: 52912.682 | AX16: 0.020307411 | AY16: 18161.699 | AZ16: 0.027198594 | BA16: 11994.858 | BB16: 0.03277779 | BC16: 18811.641 | BD16: 0.022059258
A17: 1981 | B17: 2 | C17: 54513.464 | D17: 0.024446581 | E17: 53597.137 | F17: 0.0092084691 | G17: 37242.004 | H17: 0.024556583 | I17: 32003.339 | J17: 0.024389916 | K17: 5238.6649 | L17: 0.025575941 | M17: 16355.133 | N17: -0.024081366 | O17: 16917.478 | P17: 0.021383663 | Q17: 7313.4621 | R17: 0.021884177 | S17: 9604.016 | T17: 0.02100285 | U17: 816.20961 | W17: -1378.5549 | Y17: 916.32665 | AA17: 26091.02 | AB17: 0.023118362 | AC17: 19683.711 | AD17: 0.018054852 | AE17: 13539.864 | AF17: 0.025242738 | AG17: 11968.947 | AH17: 0.015802081 | AI17: 6407.3097 | AJ17: 0.038993764 | AK17: 25174.694 | AL17: -0.0087518215 | AM17: 20562.063 | AN17: -0.016996391 | AO17: 15459.981 | AP17: 0.017459371 | AQ17: 14447.171 | AR17: 0.0080173761 | AS17: 4612.6308 | AT17: 0.029748287 | AU17: 72757.056 | AV17: 0.023674845 | AW17: 54159.482 | AX17: 0.023563361 | AY17: 18597.574 | AZ17: 0.023999644 | BA17: 12190.264 | BB17: 0.016290811 | BC17: 19059.802 | BD17: 0.013191882
A18: 1981 | B18: 3 | C18: 55709.571 | D18: 0.021941502 | E18: 56124.664 | F18: 0.047157869 | G18: 37935.577 | H18: 0.018623394 | I18: 32592.219 | J18: 0.01840058 | K18: 5343.3574 | L18: 0.019984578 | M18: 18189.087 | N18: 0.11213325 | O18: 17503.878 | P18: 0.034662372 | Q18: 7380.9368 | R18: 0.0092260979 | S18: 10122.941 | T18: 0.054032104 | U18: 893.23974 | W18: -208.03068 | Y18: -415.09286 | AA18: 27857.9 | AB18: 0.067719839 | AC18: 21189.369 | AD18: 0.076492608 | AE18: 14043.173 | AF18: 0.037172365 | AG18: 12375.463 | AH18: 0.033964245 | AI18: 6668.531 | AJ18: 0.040769268 | AK18: 28272.993 | AL18: 0.12307197 | AM18: 23556.918 | AN18: 0.14564955 | AO18: 16167.492 | AP18: 0.045764054 | AQ18: 15175.305 | AR18: 0.050399766 | AS18: 4716.0748 | AT18: 0.022426242 | AU18: 74707.711 | AV18: 0.026810529 | AW18: 55439.455 | AX18: 0.023633395 | AY18: 19268.256 | AZ18: 0.036062915 | BA18: 12599.725 | BB18: 0.033589215 | BC18: 19891.38 | BD18: 0.04362994
A19: 1981 | B19: 4 | C19: 56811.774 | D19: 0.019784806 | E19: 56389.12 | F19: 0.0047119357 | G19: 38371.556 | H19: 0.011492612 | I19: 32908.575 | J19: 0.0097064614 | K19: 5462.9812 | L19: 0.022387372 | M19: 18017.564 | N19: -0.009429997 | O19: 17073.502 | P19: -0.024587458 | Q19: 7260.1678 | R19: -0.016362299 | S19: 9813.3344 | T19: -0.030584666 | U19: 1444.2102 | W19: -500.14826 | Y19: 422.65439 | AA19: 26825.154 | AB19: -0.037071919 | AC19: 19960.892 | AD19: -0.057976096 | AE19: 13707.565 | AF19: -0.023898339 | AG19: 12293.153 | AH19: -0.0066510678 | AI19: 6864.2621 | AJ19: 0.029351451 | AK19: 26402.5 | AL19: -0.066158297 | AM19: 21607.198 | AN19: -0.082766361 | AO19: 15455.688 | AP19: -0.04402688 | AQ19: 14659.476 | AR19: -0.033991345 | AS19: 4795.3021 | AT19: 0.016799417 | AU19: 74822.342 | AV19: 0.0015343921 | AW19: 55445.058 | AX19: 0.00010106482 | AY19: 19377.284 | AZ19: 0.005658423 | BA19: 12513.022 | BB19: -0.0068813496 | BC19: 19454.778 | BD19: -0.021949293
A20: 1982 | B20: 1 | C20: 57364.509 | D20: 0.0097292392 | E20: 57046.13 | F20: 0.01165136 | G20: 38738.423 | H20: 0.0095609276 | I20: 33152.341 | J20: 0.0074073971 | K20: 5586.082 | L20: 0.022533628 | M20: 18307.706 | N20: 0.0161033 | O20: 16916.246 | P20: -0.0092105502 | Q20: 7376.3621 | R20: 0.016004354 | S20: 9539.8837 | T20: -0.027865212 | U20: 1098.2697 | W20: 293.19083 | Y20: 318.37982 | AA20: 25481.332 | AB20: -0.050095614 | AC20: 18487.348 | AD20: -0.073821555 | AE20: 13547.19 | AF20: -0.011699706 | AG20: 12128.918 | AH20: -0.01335992 | AI20: 6993.9836 | AJ20: 0.018898101 | AK20: 25162.952 | AL20: -0.046948131 | AM20: 20310.968 | AN20: -0.059990661 | AO20: 14734.362 | AP20: -0.046670549 | AQ20: 13864.659 | AR20: -0.054218669 | AS20: 4851.9842 | AT20: 0.01182033 | AU20: 74982.883 | AV20: 0.002145624 | AW20: 55654.669 | AX20: 0.003780523 | AY20: 19328.214 | AZ20: -0.002532383 | BA20: 12334.23 | BB20: -0.014288493 | BC20: 18716.643 | BD20: -0.037941077
A21: 1982 | B21: 2 | C21: 58177.413 | D21: 0.014170838 | E21: 58282.246 | F21: 0.021668712 | G21: 39628.793 | H21: 0.02298414 | I21: 33938.499 | J21: 0.023713496 | K21: 5690.2934 | L21: 0.018655553 | M21: 18653.453 | N21: 0.018885315 | O21: 17110.006 | P21: 0.011454105 | Q21: 7308.2501 | R21: -0.0092338139 | S21: 9801.7562 | T21: 0.027450273 | U21: 760.10265 | W21: 783.34418 | Y21: -104.83315 | AA21: 25189.021 | AB21: -0.011471551 | AC21: 17973.206 | AD21: -0.027810492 | AE21: 13666.667 | AF21: 0.0088193148 | AG21: 12299 | AH21: 0.014022853 | AI21: 7215.8154 | AJ21: 0.031717526 | AK21: 25293.854 | AL21: 0.0052021949 | AM21: 20398.997 | AN21: 0.0043340736 | AO21: 14909.488 | AP21: 0.01188554 | AQ21: 14137.106 | AR21: 0.019650521 | AS21: 4894.8575 | AT21: 0.008836251 | AU21: 76449.274 | AV21: 0.019556348 | AW21: 56738.799 | AX21: 0.019479584 | AY21: 19710.475 | AZ21: 0.019777384 | BA21: 12494.66 | BB21: 0.013006863 | BC21: 19031.964 | BD21: 0.016847098
A22: 1982 | B22: 3 | C22: 58624.972 | D22: 0.0076930122 | E22: 58481.934 | F22: 0.0034262266 | G22: 40332.709 | H22: 0.017762745 | I22: 34556.138 | J22: 0.01819877 | K22: 5776.5706 | L22: 0.015162173 | M22: 18149.225 | N22: -0.027031347 | O22: 17076.65 | P22: -0.0019495046 | Q22: 7299.5327 | R22: -0.0011928209 | S22: 9777.1176 | T22: -0.0025136927 | U22: 164.85581 | W22: 907.71908 | Y22: 143.03821 | AA22: 26048.375 | AB22: 0.03411622 | AC22: 18613.83 | AD22: 0.035643278 | AE22: 13238.472 | AF22: -0.031331317 | AG22: 12305.838 | AH22: 0.00055596585 | AI22: 7434.5457 | AJ22: 0.030312613 | AK22: 25905.337 | AL22: 0.024175154 | AM22: 20962.082 | AN22: 0.027603566 | AO22: 14696.104 | AP22: -0.014311969 | AQ22: 13941.392 | AR22: -0.013844053 | AS22: 4943.2553 | AT22: 0.0098874701 | AU22: 77344.763 | AV22: 0.01171351 | AW22: 57409.359 | AX22: 0.01181837 | AY22: 19935.404 | AZ22: 0.011411657 | BA22: 12500.859 | BB22: 0.00049612915 | BC22: 18884.647 | BD22: -0.007740509
A23: 1982 | B23: 4 | C23: 59092.797 | D23: 0.007979959 | E23: 58200.918 | F23: -0.0048051846 | G23: 40905.865 | H23: 0.014210713 | I23: 34982.561 | J23: 0.012340014 | K23: 5923.3039 | L23: 0.025401458 | M23: 17295.052 | N23: -0.047063884 | O23: 17265.12 | P23: 0.011036696 | Q23: 7475.6034 | R23: 0.024120827 | S23: 9789.5166 | T23: 0.0012681687 | U23: 79.173015 | W23: -49.240952 | Y23: 891.87957 | AA23: 26862.125 | AB23: 0.031239928 | AC23: 19293.488 | AD23: 0.036513612 | AE23: 13740.442 | AF23: 0.037917453 | AG23: 12410.037 | AH23: 0.0084674863 | AI23: 7568.6369 | AJ23: 0.018036234 | AK23: 25970.245 | AL23: 0.0025055845 | AM23: 20977.541 | AN23: 0.00073746851 | AO23: 15280.778 | AP23: 0.039784297 | AQ23: 14337.727 | AR23: 0.02842871 | AS23: 4992.7044 | AT23: 0.010003355 | AU23: 78344.056 | AV23: 0.012919977 | AW23: 58170.985 | AX23: 0.013266588 | AY23: 20173.07 | AZ23: 0.011921817 | BA23: 12604.434 | BB23: 0.0082854333 | BC23: 19330.432 | BD23: 0.023605679
A24: 1983 | B24: 1 | C24: 59326.143 | D24: 0.003948803 | E24: 60199.172 | F24: 0.034333722 | G24: 41364.674 | H24: 0.011216214 | I24: 35379.236 | J24: 0.011339194 | K24: 5985.4388 | L24: 0.010489902 | M24: 18834.497 | N24: 0.089010728 | O24: 17650.73 | P24: 0.022334617 | Q24: 7531.5368 | R24: 0.007482127 | S24: 10119.193 | T24: 0.033676477 | U24: -351.10316 | W24: 1534.8706 | Y24: -873.02873 | AA24: 25541.164 | AB24: -0.04917559 | AC24: 17953.443 | AD24: -0.069455787 | AE24: 13461.725 | AF24: -0.020284361 | AG24: 12340.14 | AH24: -0.0056323105 | AI24: 7587.7204 | AJ24: 0.0025214 | AK24: 26414.193 | AL24: 0.017094466 | AM24: 21434.127 | AN24: 0.021765486 | AO24: 15345.001 | AP24: 0.0042028424 | AQ24: 14470.786 | AR24: 0.0092802901 | AS24: 4980.0655 | AT24: -0.0025314725 | AU24: 79128.097 | AV24: 0.010007669 | AW24: 59015.404 | AX24: 0.01451615 | AY24: 20112.693 | AZ24: -0.002992971 | BA24: 12524.973 | BB24: -0.0063042084 | BC24: 19450.851 | BD24: 0.0062295233
... A193: 2025 | B193: 2 | C193: 209886.92 | D193: -0.00036957948 | E193: 195992.9 | F193: 0.080737142 | G193: 131449.85 | H193: 0.0027174437 | I193: 106852.53 | J193: 0.0007567326 | K193: 24597.317 | L193: 0.011324861 | M193: 64543.057 | N193: 0.28424664 | O193: 52317.993 | P193: -0.0034175427 | Q193: 17273.551 | R193: 0.0017142808 | S193: 35044.442 | T193: -0.0059277424 | U193: 7010.5428 | W193: 5214.5212 | Y193: 13894.012 | AA193: 156965.37 | AB193: -0.13746326 | AC193: 117693.8 | AD193: -0.17863254 | AE193: 89283.036 | AF193: -0.063410161 | AG193: 71288.57 | AH193: -0.06294164 | AI193: 39271.566 | AJ193: 0.015004978 | AK193: 143071.36 | AL193: -0.067135005 | AM193: 96445.588 | AN193: -0.092099162 | AO193: 60844.979 | AP193: -0.072829663 | AQ193: 58180.262 | AR193: -0.081898791 | AS193: 46625.767 | AT193: -0.010876886 | AU193: 307682.4 | AV193: -0.020020624 | AW193: 183767.84 | AX193: 0.00096315924 | AY193: 123914.56 | AZ193: -0.049568988 | BA193: 84642.996 | BB193: -0.076818796 | BC193: 104806.03 | BD193: -0.051603752

Sheet real_q
A1: =IF(INDIRECT("beschriftung!"&ADDRESS(beschriftung!$C$1*12+ROW(beschriftung!$A1)-1,COLUMN(beschriftung!A$1)))="","",INDIRECT("beschriftung!"&ADDRESS(beschriftung!$C$1*12+ROW(beschriftung!$A1)-1,COLUMN(beschriftung!A$1)))) -> ESA 2010, Quarterly aggregates of Gross Domestic Product, expenditure approach, seasonally, calendar and sport event adjusted data. Background information on sport event adjustment can be found in the publication “Konjunkturtendenzen” (“Economic Trends”) from autumn 2022 and in the technical note from 5 September 2022 on the website www.seco.admin.ch.
A2: =IF(INDIRECT("beschriftung!"&ADDRESS(beschriftung!$C$1*12+ROW(beschriftung!$A3)-1,COLUMN(beschriftung!A$1)))="","",INDIRECT("beschriftung!"&ADDRESS(beschriftung!$C$1*12+ROW(beschriftung!$A3)-1,COLUMN(beschriftung!A$1)))) -> In Mio. Swiss Francs, at prices of the preceding year, chained values ("annual overlap"), reference year 2015, percentage change to previous quarter
A3: =IF(INDIRECT("beschriftung!"&ADDRESS(beschriftung!$C$1*12+ROW(beschriftung!$A5)-1,COLUMN(beschriftung!A$1)))="","",INDIRECT("beschriftung!"&ADDRESS(beschriftung!$C$1*12+ROW(beschriftung!$A5)-1,COLUMN(beschriftung!A$1))))
C4: =IF(INDIRECT("beschriftung!"&ADDRESS(beschriftung!$C$1*12+ROW(beschriftung!$A5)-1,COLUMN(beschriftung!C$1)))="","",INDIRECT("beschriftung!"&ADDRESS(beschriftung!$C$1*12+ROW(beschriftung!$A5)-1,COLUMN(beschriftung!C$1)))) -> Gross domestic product
E5: =IF(INDIRECT("beschriftung!"&ADDRESS(beschriftung!$C$1*12+ROW(beschriftung!$A6)-1,COLUMN(beschriftung!E$1)))="","",INDIRECT("beschriftung!"&ADDRESS(beschriftung!$C$1*12+ROW(beschriftung!$A6)-1,COLUMN(beschriftung!E$1)))) -> Internal demand | Y5: =IF(INDIRECT("beschriftung!"&ADDRESS(beschriftung!$C$1*12+ROW(beschriftung!$A6)-1,COLUMN(beschriftung!Y$1)))="","",INDIRECT("beschriftung!"&ADDRESS(beschriftung!$C$1*12+ROW(beschriftung!$A6)-1,COLUMN(beschriftung!Y$1)))) -> Trade balance (goods and services) | AU5: =IF(INDIRECT("beschriftung!"&ADDRESS(beschriftung!$C$1*12+ROW(beschriftung!$A6)-1,COLUMN(beschriftung!AU$1)))="","",INDIRECT("beschriftung!"&ADDRESS(beschriftung!$C$1*12+ROW(beschriftung!$A6)-1,COLUMN(beschriftung!AU$1)))) -> Global demand excluding inventories change, stat. discrepancies and valuables
G6: =IF(INDIRECT("beschriftung!"&ADDRESS(beschriftung!$C$1*12+ROW(beschriftung!$A7)-1,COLUMN(beschriftung!G$1)))="","",INDIRECT("beschriftung!"&ADDRESS(beschriftung!$C$1*12+ROW(beschriftung!$A7)-1,COLUMN(beschriftung!G$1)))) -> Final consumption expenditure | M6: =IF(INDIRECT("beschriftung!"&ADDRESS(beschriftung!$C$1*12+ROW(beschriftung!$A7)-1,COLUMN(beschriftung!M$1)))="","",INDIRECT("beschriftung!"&ADDRESS(beschriftung!$C$1*12+ROW(beschriftung!$A7)-1,COLUMN(beschriftung!M$1)))) -> Gross capital formation | AA6: =IF(INDIRECT("beschriftung!"&ADDRESS(beschriftung!$C$1*12+ROW(beschriftung!$A7)-1,COLUMN(beschriftung!AA$1)))="","",INDIRECT("beschriftung!"&ADDRESS(beschriftung!$C$1*12+ROW(beschriftung!$A7)-1,COLUMN(beschriftung!AA$1)))) -> Exports of goods and services | AK6: =IF(INDIRECT("beschriftung!"&ADDRESS(beschriftung!$C$1*12+ROW(beschriftung!$A7)-1,COLUMN(beschriftung!AK$1)))="","",INDIRECT("beschriftung!"&ADDRESS(beschriftung!$C$1*12+ROW(beschriftung!$A7)-1,COLUMN(beschriftung!AK$1)))) -> Imports of goods and services | AW6: =IF(INDIRECT("beschriftung!"&ADDRESS(beschriftung!$C$1*12+ROW(beschriftung!$A7)-1,COLUMN(beschriftung!AW$1)))="","",INDIRECT("beschriftung!"&ADDRESS(beschriftung!$C$1*12+ROW(beschriftung!$A7)-1,COLUMN(beschriftung!AW$1)))) -> Final domestic demand | AY6: =IF(INDIRECT("beschriftung!"&ADDRESS(beschriftung!$C$1*12+ROW(beschriftung!$A7)-1,COLUMN(beschriftung!AY$1)))="","",INDIRECT("beschriftung!"&ADDRESS(beschriftung!$C$1*12+ROW(beschriftung!$A7)-1,COLUMN(beschriftung!AY$1)))) -> Exports of goods and services (excluding valuables) | BC6: =IF(INDIRECT("beschriftung!"&ADDRESS(beschriftung!$C$1*12+ROW(beschriftung!$A7)-1,COLUMN(beschriftung!BC$1)))="","",INDIRECT("beschriftung!"&ADDRESS(beschriftung!$C$1*12+ROW(beschriftung!$A7)-1,COLUMN(beschriftung!BC$1)))) -> Imports of goods and services (excluding valuables)
I7: =IF(INDIRECT("beschriftung!"&ADDRESS(beschriftung!$C$1*12+ROW(beschriftung!$A8)-1,COLUMN(beschriftung!I$1)))="","",INDIRECT("beschriftung!"&ADDRESS(beschriftung!$C$1*12+ROW(beschriftung!$A8)-1,COLUMN(beschriftung!I$1)))) -> Households and NPISH | K7: =IF(INDIRECT("beschriftung!"&ADDRESS(beschriftung!$C$1*12+ROW(beschriftung!$A8)-1,COLUMN(beschriftung!K$1)))="","",INDIRECT("beschriftung!"&ADDRESS(beschriftung!$C$1*12+ROW(beschriftung!$A8)-1,COLUMN(beschriftung!K$1)))) -> General government | O7: =IF(INDIRECT("beschriftung!"&ADDRESS(beschriftung!$C$1*12+ROW(beschriftung!$A8)-1,COLUMN(beschriftung!O$1)))="","",INDIRECT("beschriftung!"&ADDRESS(beschriftung!$C$1*12+ROW(beschriftung!$A8)-1,COLUMN(beschriftung!O$1)))) -> Gross fixed capital formation | U7: =IF(INDIRECT("beschriftung!"&ADDRESS(beschriftung!$C$1*12+ROW(beschriftung!$A8)-1,COLUMN(beschriftung!U$1)))="","",INDIRECT("beschriftung!"&ADDRESS(beschriftung!$C$1*12+ROW(beschriftung!$A8)-1,COLUMN(beschriftung!U$1)))) -> Changes in inventories and statistical discrepancies | W7: =IF(INDIRECT("beschriftung!"&ADDRESS(beschriftung!$C$1*12+ROW(beschriftung!$A8)-1,COLUMN(beschriftung!W$1)))="","",INDIRECT("beschriftung!"&ADDRESS(beschriftung!$C$1*12+ROW(beschriftung!$A8)-1,COLUMN(beschriftung!W$1)))) -> Acquisitions less disposals of valuables | AC7: =IF(INDIRECT("beschriftung!"&ADDRESS(beschriftung!$C$1*12+ROW(beschriftung!$A8)-1,COLUMN(beschriftung!AC$1)))="","",INDIRECT("beschriftung!"&ADDRESS(beschriftung!$C$1*12+ROW(beschriftung!$A8)-1,COLUMN(beschriftung!AC$1)))) -> Exports (exp.) of goods | AI7: =IF(INDIRECT("beschriftung!"&ADDRESS(beschriftung!$C$1*12+ROW(beschriftung!$A8)-1,COLUMN(beschriftung!AI$1)))="","",INDIRECT("beschriftung!"&ADDRESS(beschriftung!$C$1*12+ROW(beschriftung!$A8)-1,COLUMN(beschriftung!AI$1)))) -> Exports of services | AM7: =IF(INDIRECT("beschriftung!"&ADDRESS(beschriftung!$C$1*12+ROW(beschriftung!$A8)-1,COLUMN(beschriftung!AM$1)))="","",INDIRECT("beschriftung!"&ADDRESS(beschriftung!$C$1*12+ROW(beschriftung!$A8)-1,COLUMN(beschriftung!AM$1)))) -> Imports (imp.) of goods | AS7: =IF(INDIRECT("beschriftung!"&ADDRESS(beschriftung!$C$1*12+ROW(beschriftung!$A8)-1,COLUMN(beschriftung!AS$1)))="","",INDIRECT("beschriftung!"&ADDRESS(beschriftung!$C$1*12+ROW(beschriftung!$A8)-1,COLUMN(beschriftung!AS$1)))) -> Imports of services | BA7: =IF(INDIRECT("beschriftung!"&ADDRESS(beschriftung!$C$1*12+ROW(beschriftung!$A8)-1,COLUMN(beschriftung!BA$1)))="","",INDIRECT("beschriftung!"&ADDRESS(beschriftung!$C$1*12+ROW(beschriftung!$A8)-1,COLUMN(beschriftung!BA$1)))) -> thereof exports of goods excluding valuables
Q8: =IF(INDIRECT("beschriftung!"&ADDRESS(beschriftung!$C$1*12+ROW(beschriftung!$A9)-1,COLUMN(beschriftung!Q$1)))="","",INDIRECT("beschriftung!"&ADDRESS(beschriftung!$C$1*12+ROW(beschriftung!$A9)-1,COLUMN(beschriftung!Q$1)))) -> Construction | S8: =IF(INDIRECT("beschriftung!"&ADDRESS(beschriftung!$C$1*12+ROW(beschriftung!$A9)-1,COLUMN(beschriftung!S$1)))="","",INDIRECT("beschriftung!"&ADDRESS(beschriftung!$C$1*12+ROW(beschriftung!$A9)-1,COLUMN(beschriftung!S$1)))) -> Fixed assets and software | AE8: =IF(INDIRECT("beschriftung!"&ADDRESS(beschriftung!$C$1*12+ROW(beschriftung!$A9)-1,COLUMN(beschriftung!AE$1)))="","",INDIRECT("beschriftung!"&ADDRESS(beschriftung!$C$1*12+ROW(beschriftung!$A9)-1,COLUMN(beschriftung!AE$1)))) -> thereof exp. of goods excluding non-monetary gold | AG8: =IF(INDIRECT("beschriftung!"&ADDRESS(beschriftung!$C$1*12+ROW(beschriftung!$A9)-1,COLUMN(beschriftung!AG$1)))="","",INDIRECT("beschriftung!"&ADDRESS(beschriftung!$C$1*12+ROW(beschriftung!$A9)-1,COLUMN(beschriftung!AG$1)))) -> thereof exp. of goods excluding valuables and merchanting | AO8: =IF(INDIRECT("beschriftung!"&ADDRESS(beschriftung!$C$1*12+ROW(beschriftung!$A9)-1,COLUMN(beschriftung!AO$1)))="","",INDIRECT("beschriftung!"&ADDRESS(beschriftung!$C$1*12+ROW(beschriftung!$A9)-1,COLUMN(beschriftung!AO$1)))) -> thereof imp. of goods excluding non-monetary gold | AQ8: =IF(INDIRECT("beschriftung!"&ADDRESS(beschriftung!$C$1*12+ROW(beschriftung!$A9)-1,COLUMN(beschriftung!AQ$1)))="","",INDIRECT("beschriftung!"&ADDRESS(beschriftung!$C$1*12+ROW(beschriftung!$A9)-1,COLUMN(beschriftung!AQ$1)))) -> thereof imp. of goods excluding valuables
C11: B.1*b | E11: P.3+P.5 | G11: P.3 | I11: S.14+S15 | K11: S.13 | M11: P.5 | O11: P.51 | Q11: P.5111c | S11: P.5111be | U11: P.52 | W11: P.53 | AA11: P.6 | AC11: P.61 | AI11: P.62 | AK11: P.7 | AM11: P.71 | AS11: P.72 | AW11: P.3+P.51
A12: 1980 | B12: 1 | C12: 90356.053 | E12: 90154.083 | G12: 59792.713 | I12: 50174.554 | K12: 9437.6302 | M12: 30112.351 | O12: 20667.654 | Q12: 10057.306 | S12: 11232.882 | AA12: 26016.149 | AC12: 16877.284 | AE12: 13824.058 | AG12: 13298.866 | AI12: 9480.5561 | AK12: 24856.425 | AM12: 19623.109 | AO12: 13889.035 | AQ12: 13128.325 | AS12: 5186.7571 | AU12: 102215.07 | AW12: 80279.158 | AY12: 23141.32 | BA12: 13756.815 | BC12: 18530.27
A13: 1980 | B13: 2 | C13: 90496.493 | D13: 0.0015542904 | E13: 86135.573 | F13: -0.044573798 | G13: 59975.808 | H13: 0.0030621578 | I13: 50203.003 | J13: 0.00056701017 | K13: 9615.495 | L13: 0.018846346 | M13: 26249.315 | N13: -0.1282874 | O13: 20445.508 | P13: -0.010748459 | Q13: 10330.468 | R13: 0.02716053 | S13: 10833.545 | T13: -0.03555073 | AA13: 26391.787 | AB13: 0.014438669 | AC13: 17061.885 | AD13: 0.010937817 | AE13: 13616.164 | AF13: -0.015038588 | AG13: 13213.958 | AH13: -0.0063845823 | AI13: 9720.9659 | AJ13: 0.025358195 | AK13: 22848.725 | AL13: -0.080771887 | AM13: 17718.929 | AN13: -0.097037623 | AO13: 13313.017 | AP13: -0.041472867 | AQ13: 12835.903 | AR13: -0.022274108 | AS13: 5235.5394 | AT13: 0.009405165 | AU13: 102236.84 | AV13: 0.00021295083 | AW13: 80181.573 | AX13: -0.0012155699 | AY13: 23244.525 | AZ13: 0.0044598124 | BA13: 13674.095 | BB13: -0.006012997 | BC13: 18250.822 | BD13: -0.015080629
A14: 1980 | B14: 3 | C14: 90957.631 | D14: 0.0050956481 | E14: 85487.126 | F14: -0.0075282101 | G14: 60196.213 | H14: 0.0036749075 | I14: 50332.773 | J14: 0.0025849088 | K14: 9715.9688 | L14: 0.010449157 | M14: 25456.371 | N14: -0.030208188 | O14: 20624.729 | P14: 0.0087657853 | Q14: 10541.657 | R14: 0.020443386 | S14: 10838.558 | T14: 0.00046274896 | AA14: 26830.901 | AB14: 0.016638286 | AC14: 17282.75 | AD14: 0.012944917 | AE14: 13623.399 | AF14: 0.00053141565 | AG14: 13298.275 | AH14: 0.0063809297 | AI14: 9991.3878 | AJ14: 0.027818418 | AK14: 22596.294 | AL14: -0.011047926 | AM14: 17438.874 | AN14: -0.01580542 | AO14: 13668.646 | AP14: 0.026712859 | AQ14: 13338.851 | AR14: 0.039182888 | AS14: 5297.65 | AT14: 0.011863265 | AU14: 102999.43 | AV14: 0.0074590181 | AW14: 80601.892 | AX14: 0.0052420897 | AY14: 23569.732 | AZ14: 0.013990665 | BA14: 13769.226 | BB14: 0.0069570444 | BC14: 18849.529 | BD14: 0.032804355
A15: 1980 | B15: 4 | C15: 91483.531 | D15: 0.0057818094 | E15: 85278.969 | F15: -0.002434956 | G15: 60492.778 | H15: 0.0049266278 | I15: 50576.117 | J15: 0.0048346904 | K15: 9769.3473 | L15: 0.0054938936 | M15: 24998.277 | N15: -0.017995257 | O15: 20847.829 | P15: 0.010817093 | Q15: 10716.589 | R15: 0.016594289 | S15: 10909.789 | T15: 0.0065720188 | AA15: 27326.023 | AB15: 0.018453421 | AC15: 17584.271 | AD15: 0.017446396 | AE15: 14006.926 | AF15: 0.028152073 | AG15: 13311.108 | AH15: 0.00096497787 | AI15: 10206.953 | AJ15: 0.021575126 | AK15: 22616.114 | AL15: 0.00087714788 | AM15: 17442.156 | AN15: 0.00018822402 | AO15: 13341.184 | AP15: -0.023957161 | AQ15: 12855.366 | AR15: -0.036246355 | AS15: 5319.6402 | AT15: 0.004150937 | AU15: 103743.5 | AV15: 0.0072240697 | AW15: 81146.033 | AX15: 0.0067509669 | AY15: 23772.836 | AZ15: 0.0086171496 | BA15: 13795.606 | BB15: 0.001915866 | BC15: 18341.961 | BD15: -0.026927353
A16: 1981 | B16: 1 | C16: 91447.508 | D16: -0.00039375678 | E16: 84405.042 | F16: -0.010247855 | G16: 60485.098 | H16: -0.00012695011 | I16: 50526.634 | J16: -0.00097837318 | K16: 9819.2274 | L16: 0.0051057686 | M16: 24204.096 | N16: -0.031769441 | O16: 20874.085 | P16: 0.0012594009 | Q16: 10889.229 | R16: 0.016109651 | S16: 10802.547 | T16: -0.0098299286 | AA16: 28521.498 | AB16: 0.043748558 | AC16: 18569.475 | AD16: 0.056027562 | AE16: 14308.381 | AF16: 0.021521825 | AG16: 13517.67 | AH16: 0.015518061 | AI16: 10273.101 | AJ16: 0.0064806377 | AK16: 23135.562 | AL16: 0.022968032 | AM16: 17888.173 | AN16: 0.025571191 | AO16: 12918.594 | AP16: -0.031675579 | AQ16: 12639.386 | AR16: -0.016800752 | AS16: 5375.3429 | AT16: 0.010471139 | AU16: 104104.52 | AV16: 0.003479901 | AW16: 81170.316 | AX16: 0.00029925764 | AY16: 24077.228 | AZ16: 0.012804191 | BA16: 14018.778 | BB16: 0.016177036 | BC16: 18151.176 | BD16: -0.01040157
A17: 1981 | B17: 2 | C17: 92492.736 | D17: 0.011429814 | E17: 83787.19 | F17: -0.0073200921 | G17: 60946.718 | H17: 0.0076319639 | I17: 50932.746 | J17: 0.0080375865 | K17: 9869.8007 | L17: 0.0051504354 | M17: 23226.786 | N17: -0.040377881 | O17: 20901.836 | P17: 0.001329477 | Q17: 10884.446 | R17: -0.00043922536 | S17: 10831.339 | T17: 0.0026653379 | AA17: 29602.998 | AB17: 0.037918779 | AC17: 19341.916 | AD17: 0.04159732 | AE17: 14958.728 | AF17: 0.045452163 | AG17: 13813.112 | AH17: 0.021855972 | AI17: 10541.875 | AJ17: 0.0261629 | AK17: 23136.71 | AL17: 4.9643218e-05 | AM17: 17798.884 | AN17: -0.0049915414 | AO17: 13248.488 | AP17: 0.025536337 | AQ17: 12693.934 | AR17: 0.0043157012 | AS17: 5505.8242 | AT17: 0.024274036 | AU17: 105169.55 | AV17: 0.010230425 | AW17: 81630.626 | AX17: 0.0056709088 | AY17: 24641.026 | AZ17: 0.023416258 | BA17: 14326.863 | BB17: 0.02197654 | BC17: 18316.937 | BD17: 0.0091322721
A18: 1981 | B18: 3 | C18: 92813.975 | D18: 0.0034731278 | E18: 86717.117 | F18: 0.034968685 | G18: 60890.497 | H18: -0.00092246055 | I18: 50886.005 | J18: -0.00091770404 | K18: 9860.4081 | L18: -0.0009516437 | M18: 25974.308 | N18: 0.11829111 | O18: 21304.253 | P18: 0.019252698 | Q18: 10834.081 | R18: -0.0046272676 | S18: 11234.621 | T18: 0.037232851 | AA18: 32284.474 | AB18: 0.09058125 | AC18: 21525.69 | AD18: 0.11290374 | AE18: 15627.33 | AF18: 0.044696468 | AG18: 14123.326 | AH18: 0.022457881 | AI18: 10733.421 | AJ18: 0.018170058 | AK18: 26847.052 | AL18: 0.16036601 | AM18: 21186.706 | AN18: 0.19033906 | AO18: 13931.576 | AP18: 0.051559684 | AQ18: 13266.319 | AR18: 0.045091236 | AS18: 5618.4283 | AT18: 0.020451817 | AU18: 106149.08 | AV18: 0.0093137514 | AW18: 82065.558 | AX18: 0.005328056 | AY18: 25149.624 | AZ18: 0.02064027 | BA18: 14641.2 | BB18: 0.021940394 | BC18: 19032.319 | BD18: 0.039055751
A19: 1981 | B19: 4 | C19: 92465.756 | D19: -0.0037517981 | E19: 86146.1 | F19: -0.0065848286 | G19: 60908.59 | H19: 0.00029712751 | I19: 50897.885 | J19: 0.0002334499 | K19: 9867.1904 | L19: 0.00068782827 | M19: 25432.527 | N19: -0.020858339 | O19: 20519.227 | P19: -0.036848295 | Q19: 10547.285 | R19: -0.026471688 | S19: 10736.411 | T19: -0.044345935 | AA19: 32215.198 | AB19: -0.0021458182 | AC19: 21387.368 | AD19: -0.0064259167 | AE19: 15200.56 | AF19: -0.027309236 | AG19: 13788.817 | AH19: -0.02368486 | AI19: 10873.279 | AJ19: 0.013030069 | AK19: 26651.061 | AL19: -0.0073002735 | AM19: 20874.46 | AN19: -0.014737831 | AO19: 13805.975 | AP19: -0.0090155397 | AQ19: 13249.476 | AR19: -0.0012695918 | AS19: 5804.9504 | AT19: 0.033198271 | AU19: 104944.74 | AV19: -0.011345694 | AW19: 81132.441 | AX19: -0.011370387 | AY19: 24866.022 | AZ19: -0.011276577 | BA19: 14289.482 | BB19: -0.024022476 | BC19: 19165.968 | BD19: 0.0070222258
A20: 1982 | B20: 1 | C20: 91825.683 | D20: -0.0069222739 | E20: 86711.414 | F20: 0.0065622693 | G20: 60700.815 | H20: -0.0034112598 | I20: 50693.894 | J20: -0.0040078464 | K20: 9869.3969 | L20: 0.00022361763 | M20: 26129.998 | N20: 0.027424348 | O20: 20090.606 | P20: -0.020888759 | Q20: 10552.039 | R20: 0.00045073931 | S20: 10342.416 | T20: -0.03669711 | AA20: 30849.191 | AB20: -0.042402546 | AC20: 20298.946 | AD20: -0.050890891 | AE20: 15042.891 | AF20: -0.010372588 | AG20: 13419.54 | AH20: -0.02678084 | AI20: 10727.805 | AJ20: -0.013379033 | AK20: 26254.345 | AL20: -0.014885585 | AM20: 20432.011 | AN20: -0.021195738 | AO20: 13501.038 | AP20: -0.022087311 | AQ20: 12724.87 | AR20: -0.039594499 | AS20: 5905.8033 | AT20: 0.017373599 | AU20: 103633.94 | AV20: -0.012490421 | AW20: 80415.81 | AX20: -0.0088328542 | AY20: 24300.054 | AZ20: -0.022760688 | BA20: 13891.357 | BB20: -0.027861418 | BC20: 18672.96 | BD20: -0.025723095
A21: 1982 | B21: 2 | C21: 91228.14 | D21: -0.0065073617 | E21: 86819.634 | F21: 0.0012480521 | G21: 60989.128 | H21: 0.0047497438 | I21: 50974.084 | J21: 0.0055271027 | K21: 9869.7582 | L21: 3.6613554e-05 | M21: 25975.837 | N21: -0.0058997537 | O21: 20093.263 | P21: 0.00013221782 | Q21: 10345.998 | R21: -0.019526137 | S21: 10500.451 | T21: 0.015280295 | AA21: 30074.126 | AB21: -0.025124337 | AC21: 19643.666 | AD21: -0.032281475 | AE21: 15164.251 | AF21: 0.0080676316 | AG21: 13369.73 | AH21: -0.0037117623 | AI21: 10692.432 | AJ21: -0.0032972754 | AK21: 26021.407 | AL21: -0.0088723371 | AM21: 20211.095 | AN21: -0.010812236 | AO21: 13376.674 | AP21: -0.009211423 | AQ21: 12626.455 | AR21: -0.0077340624 | AS21: 5906.3639 | AT21: 9.491955e-05 | AU21: 103780.69 | AV21: 0.0014161033 | AW21: 80684.805 | AX21: 0.0033450426 | AY21: 24198.671 | AZ21: -0.0041721228 | BA21: 13826.69 | BB21: -0.0046551968 | BC21: 18565.832 | BD21: -0.00573706
A22: 1982 | B22: 3 | C22: 90746.527 | D22: -0.0052792184 | E22: 85927.521 | F22: -0.010275479 | G22: 61114.887 | H22: 0.0020619905 | I22: 51084.509 | J22: 0.0021662886 | K22: 9883.8341 | L22: 0.0014261591 | M22: 25047.745 | N22: -0.035729047 | O22: 19919.728 | P22: -0.0086364551 | Q22: 10302.583 | R22: -0.0041962921 | S22: 10375.069 | T22: -0.011940602 | AA22: 29297.166 | AB22: -0.025834818 | AC22: 18909.056 | AD22: -0.037396762 | AE22: 14253.656 | AF22: -0.060048824 | AG22: 13101.239 | AH22: -0.020082006 | AI22: 10782.25 | AJ22: 0.0084001722 | AK22: 25111.836 | AL22: -0.034954737 | AM22: 19334.743 | AN22: -0.043359951 | AO22: 12992.736 | AP22: -0.028702042 | AQ22: 12204.214 | AR22: -0.033440964 | AS22: 5926.8881 | AT22: 0.0034749344 | AU22: 103427.45 | AV22: -0.0034037111 | AW22: 80589.421 | AX22: -0.0011821705 | AY22: 23959.39 | AZ22: -0.0098881994 | BA22: 13550.149 | BB22: -0.020000466 | BC22: 18120.822 | BD22: -0.02396929
A23: 1982 | B23: 4 | C23: 90471.18 | D23: -0.003034234 | E23: 83771.855 | F23: -0.025087022 | G23: 61303.596 | H23: 0.0030877697 | I23: 51132.305 | J23: 0.00093562856 | K23: 10044.126 | L23: 0.016217547 | M23: 22906.342 | N23: -0.085492841 | O23: 20026.972 | P23: 0.0053838193 | Q23: 10534.669 | R23: 0.022526985 | S23: 10297.534 | T23: -0.0074732542 | AA23: 30006.321 | AB23: 0.024205579 | AC23: 19457.506 | AD23: 0.02900461 | AE23: 15337.356 | AF23: 0.076029664 | AG23: 13409.857 | AH23: 0.023556394 | AI23: 10896.984 | AJ23: 0.01064097 | AK23: 24536.677 | AL23: -0.022903903 | AM23: 18795.51 | AN23: -0.027889331 | AO23: 13525.459 | AP23: 0.041001541 | AQ23: 12492.08 | AR23: 0.02358743 | AS23: 5919.9313 | AT23: -0.0011737684 | AU23: 104205.35 | AV23: 0.0075211623 | AW23: 80893.954 | AX23: 0.00377882 | AY23: 24403.616 | AZ23: 0.018540792 | BA23: 13862.283 | BB23: 0.023035462 | BC23: 18429.886 | BD23: 0.017055703
A24: 1983 | B24: 1 | C24: 91221.823 | D24: 0.0082970355 | E24: 87337.722 | F24: 0.042566397 | G24: 61944.357 | H24: 0.010452264 | I24: 51698.844 | J24: 0.011079865 | K24: 10110.329 | L24: 0.0065912095 | M24: 25615.536 | N24: 0.11827266 | O24: 20382.505 | P24: 0.017752675 | Q24: 10603.475 | R24: 0.0065313124 | S24: 10569.598 | T24: 0.02642033 | AA24: 28914.789 | AB24: -0.036376736 | AC24: 18314.816 | AD24: -0.058727497 | AE24: 14998.082 | AF24: -0.022120792 | AG24: 13487.608 | AH24: 0.0057980141 | AI24: 11092.258 | AJ24: 0.017920023 | AK24: 25433.176 | AL24: 0.036537097 | AM24: 19621.418 | AN24: 0.043941771 | AO24: 13869.174 | AP24: 0.025412452 | AQ24: 12998.938 | AR24: 0.040574305 | AS24: 5947.6562 | AT24: 0.0046833092 | AU24: 105448.23 | AV24: 0.011927271 | AW24: 81917.001 | AX24: 0.012646763 | AY24: 24643.314 | AZ24: 0.0098222273 | BA24: 13931.116 | BB24: 0.0049654461 | BC24: 19005.986 | BD24: 0.031259007
... A193: 2025 | B193: 2 | C193: 197858.18 | D193: 0.0012452521 | E193: 175032.59 | F193: 0.055625099 | G193: 121406.49 | H193: 0.0039108679 | I193: 99635.589 | J193: 0.0028087115 | K193: 21790.672 | L193: 0.0087642761 | M193: 53555.784 | N193: 0.18580449 | O193: 48224.703 | P193: -0.005879806 | Q193: 14891.408 | R193: -0.0014594226 | S193: 33344.362 | T193: -0.0080366999 | AA193: 134623.41 | AB193: -0.11290088 | AC193: 97258.298 | AD193: -0.15277753 | AE193: 88733.233 | AF193: -0.037208019 | AG193: 77330.646 | AH193: -0.040791035 | AI193: 37187.645 | AJ193: 0.021326974 | AK193: 111022.08 | AL193: -0.064979069 | AM193: 71486.306 | AN193: -0.096867966 | AO193: 57857.675 | AP193: -0.060896901 | AQ193: 56316.129 | AR193: -0.065824144 | AS193: 39741.812 | AT193: 0.0010070091 | AU193: 292423.46 | AV193: -0.01034511 | AW193: 169618.7 | AX193: 0.0011094793 | AY193: 123333.15 | AZ193: -0.026515942 | BA193: 86224.232 | BB193: -0.047135906 | BC193: 95992.543 | BD193: -0.037396523

Sheet defl_q
A1: =IF(INDIRECT("beschriftung!"&ADDRESS(beschriftung!$C$1*12+ROW(beschriftung!$A1)-1,COLUMN(beschriftung!A$1)))="","",INDIRECT("beschriftung!"&ADDRESS(beschriftung!$C$1*12+ROW(beschriftung!$A1)-1,COLUMN(beschriftung!A$1)))) -> ESA 2010, Quarterly aggregates of Gross Domestic Product, expenditure approach, seasonally, calendar and sport event adjusted data. Background information on sport event adjustment can be found in the publication “Konjunkturtendenzen” (“Economic Trends”) from autumn 2022 and in the technical note from 5 September 2022 on the website www.seco.admin.ch.
A2: =IF(INDIRECT("beschriftung!"&ADDRESS(beschriftung!$C$1*12+ROW(beschriftung!$A4)-1,COLUMN(beschriftung!A$1)))="","",INDIRECT("beschriftung!"&ADDRESS(beschriftung!$C$1*12+ROW(beschriftung!$A4)-1,COLUMN(beschriftung!A$1)))) -> Implicit chain price indexes, percentage change to previous quarter
A3: =IF(INDIRECT("beschriftung!"&ADDRESS(beschriftung!$C$1*12+ROW(beschriftung!$A5)-1,COLUMN(beschriftung!A$1)))="","",INDIRECT("beschriftung!"&ADDRESS(beschriftung!$C$1*12+ROW(beschriftung!$A5)-1,COLUMN(beschriftung!A$1))))
C4: =IF(INDIRECT("beschriftung!"&ADDRESS(beschriftung!$C$1*12+ROW(beschriftung!$A5)-1,COLUMN(beschriftung!C$1)))="","",INDIRECT("beschriftung!"&ADDRESS(beschriftung!$C$1*12+ROW(beschriftung!$A5)-1,COLUMN(beschriftung!C$1)))) -> Gross domestic product
E5: =IF(INDIRECT("beschriftung!"&ADDRESS(beschriftung!$C$1*12+ROW(beschriftung!$A6)-1,COLUMN(beschriftung!E$1)))="","",INDIRECT("beschriftung!"&ADDRESS(beschriftung!$C$1*12+ROW(beschriftung!$A6)-1,COLUMN(beschriftung!E$1)))) -> Internal demand | Y5: =IF(INDIRECT("beschriftung!"&ADDRESS(beschriftung!$C$1*12+ROW(beschriftung!$A6)-1,COLUMN(beschriftung!Y$1)))="","",INDIRECT("beschriftung!"&ADDRESS(beschriftung!$C$1*12+ROW(beschriftung!$A6)-1,COLUMN(beschriftung!Y$1)))) -> Trade balance (goods and services) | AU5: =IF(INDIRECT("beschriftung!"&ADDRESS(beschriftung!$C$1*12+ROW(beschriftung!$A6)-1,COLUMN(beschriftung!AU$1)))="","",INDIRECT("beschriftung!"&ADDRESS(beschriftung!$C$1*12+ROW(beschriftung!$A6)-1,COLUMN(beschriftung!AU$1)))) -> Global demand excluding inventories change, stat. discrepancies and valuables
G6: =IF(INDIRECT("beschriftung!"&ADDRESS(beschriftung!$C$1*12+ROW(beschriftung!$A7)-1,COLUMN(beschriftung!G$1)))="","",INDIRECT("beschriftung!"&ADDRESS(beschriftung!$C$1*12+ROW(beschriftung!$A7)-1,COLUMN(beschriftung!G$1)))) -> Final consumption expenditure | M6: =IF(INDIRECT("beschriftung!"&ADDRESS(beschriftung!$C$1*12+ROW(beschriftung!$A7)-1,COLUMN(beschriftung!M$1)))="","",INDIRECT("beschriftung!"&ADDRESS(beschriftung!$C$1*12+ROW(beschriftung!$A7)-1,COLUMN(beschriftung!M$1)))) -> Gross capital formation | AA6: =IF(INDIRECT("beschriftung!"&ADDRESS(beschriftung!$C$1*12+ROW(beschriftung!$A7)-1,COLUMN(beschriftung!AA$1)))="","",INDIRECT("beschriftung!"&ADDRESS(beschriftung!$C$1*12+ROW(beschriftung!$A7)-1,COLUMN(beschriftung!AA$1)))) -> Exports of goods and services | AK6: =IF(INDIRECT("beschriftung!"&ADDRESS(beschriftung!$C$1*12+ROW(beschriftung!$A7)-1,COLUMN(beschriftung!AK$1)))="","",INDIRECT("beschriftung!"&ADDRESS(beschriftung!$C$1*12+ROW(beschriftung!$A7)-1,COLUMN(beschriftung!AK$1)))) -> Imports of goods and services | AW6: =IF(INDIRECT("beschriftung!"&ADDRESS(beschriftung!$C$1*12+ROW(beschriftung!$A7)-1,COLUMN(beschriftung!AW$1)))="","",INDIRECT("beschriftung!"&ADDRESS(beschriftung!$C$1*12+ROW(beschriftung!$A7)-1,COLUMN(beschriftung!AW$1)))) -> Final domestic demand | AY6: =IF(INDIRECT("beschriftung!"&ADDRESS(beschriftung!$C$1*12+ROW(beschriftung!$A7)-1,COLUMN(beschriftung!AY$1)))="","",INDIRECT("beschriftung!"&ADDRESS(beschriftung!$C$1*12+ROW(beschriftung!$A7)-1,COLUMN(beschriftung!AY$1)))) -> Exports of goods and services (excluding valuables) | BC6: =IF(INDIRECT("beschriftung!"&ADDRESS(beschriftung!$C$1*12+ROW(beschriftung!$A7)-1,COLUMN(beschriftung!BC$1)))="","",INDIRECT("beschriftung!"&ADDRESS(beschriftung!$C$1*12+ROW(beschriftung!$A7)-1,COLUMN(beschriftung!BC$1)))) -> Imports of goods and services (excluding valuables)
I7: =IF(INDIRECT("beschriftung!"&ADDRESS(beschriftung!$C$1*12+ROW(beschriftung!$A8)-1,COLUMN(beschriftung!I$1)))="","",INDIRECT("beschriftung!"&ADDRESS(beschriftung!$C$1*12+ROW(beschriftung!$A8)-1,COLUMN(beschriftung!I$1)))) -> Households and NPISH | K7: =IF(INDIRECT("beschriftung!"&ADDRESS(beschriftung!$C$1*12+ROW(beschriftung!$A8)-1,COLUMN(beschriftung!K$1)))="","",INDIRECT("beschriftung!"&ADDRESS(beschriftung!$C$1*12+ROW(beschriftung!$A8)-1,COLUMN(beschriftung!K$1)))) -> General government | O7: =IF(INDIRECT("beschriftung!"&ADDRESS(beschriftung!$C$1*12+ROW(beschriftung!$A8)-1,COLUMN(beschriftung!O$1)))="","",INDIRECT("beschriftung!"&ADDRESS(beschriftung!$C$1*12+ROW(beschriftung!$A8)-1,COLUMN(beschriftung!O$1)))) -> Gross fixed capital formation | U7: =IF(INDIRECT("beschriftung!"&ADDRESS(beschriftung!$C$1*12+ROW(beschriftung!$A8)-1,COLUMN(beschriftung!U$1)))="","",INDIRECT("beschriftung!"&ADDRESS(beschriftung!$C$1*12+ROW(beschriftung!$A8)-1,COLUMN(beschriftung!U$1)))) -> Changes in inventories and statistical discrepancies | W7: =IF(INDIRECT("beschriftung!"&ADDRESS(beschriftung!$C$1*12+ROW(beschriftung!$A8)-1,COLUMN(beschriftung!W$1)))="","",INDIRECT("beschriftung!"&ADDRESS(beschriftung!$C$1*12+ROW(beschriftung!$A8)-1,COLUMN(beschriftung!W$1)))) -> Acquisitions less disposals of valuables | AC7: =IF(INDIRECT("beschriftung!"&ADDRESS(beschriftung!$C$1*12+ROW(beschriftung!$A8)-1,COLUMN(beschriftung!AC$1)))="","",INDIRECT("beschriftung!"&ADDRESS(beschriftung!$C$1*12+ROW(beschriftung!$A8)-1,COLUMN(beschriftung!AC$1)))) -> Exports (exp.) of goods | AI7: =IF(INDIRECT("beschriftung!"&ADDRESS(beschriftung!$C$1*12+ROW(beschriftung!$A8)-1,COLUMN(beschriftung!AI$1)))="","",INDIRECT("beschriftung!"&ADDRESS(beschriftung!$C$1*12+ROW(beschriftung!$A8)-1,COLUMN(beschriftung!AI$1)))) -> Exports of services | AM7: =IF(INDIRECT("beschriftung!"&ADDRESS(beschriftung!$C$1*12+ROW(beschriftung!$A8)-1,COLUMN(beschriftung!AM$1)))="","",INDIRECT("beschriftung!"&ADDRESS(beschriftung!$C$1*12+ROW(beschriftung!$A8)-1,COLUMN(beschriftung!AM$1)))) -> Imports (imp.) of goods | AS7: =IF(INDIRECT("beschriftung!"&ADDRESS(beschriftung!$C$1*12+ROW(beschriftung!$A8)-1,COLUMN(beschriftung!AS$1)))="","",INDIRECT("beschriftung!"&ADDRESS(beschriftung!$C$1*12+ROW(beschriftung!$A8)-1,COLUMN(beschriftung!AS$1)))) -> Imports of services | BA7: =IF(INDIRECT("beschriftung!"&ADDRESS(beschriftung!$C$1*12+ROW(beschriftung!$A8)-1,COLUMN(beschriftung!BA$1)))="","",INDIRECT("beschriftung!"&ADDRESS(beschriftung!$C$1*12+ROW(beschriftung!$A8)-1,COLUMN(beschriftung!BA$1)))) -> thereof exports of goods excluding valuables
Q8: =IF(INDIRECT("beschriftung!"&ADDRESS(beschriftung!$C$1*12+ROW(beschriftung!$A9)-1,COLUMN(beschriftung!Q$1)))="","",INDIRECT("beschriftung!"&ADDRESS(beschriftung!$C$1*12+ROW(beschriftung!$A9)-1,COLUMN(beschriftung!Q$1)))) -> Construction | S8: =IF(INDIRECT("beschriftung!"&ADDRESS(beschriftung!$C$1*12+ROW(beschriftung!$A9)-1,COLUMN(beschriftung!S$1)))="","",INDIRECT("beschriftung!"&ADDRESS(beschriftung!$C$1*12+ROW(beschriftung!$A9)-1,COLUMN(beschriftung!S$1)))) -> Fixed assets and software | AE8: =IF(INDIRECT("beschriftung!"&ADDRESS(beschriftung!$C$1*12+ROW(beschriftung!$A9)-1,COLUMN(beschriftung!AE$1)))="","",INDIRECT("beschriftung!"&ADDRESS(beschriftung!$C$1*12+ROW(beschriftung!$A9)-1,COLUMN(beschriftung!AE$1)))) -> thereof exp. of goods excluding non-monetary gold | AG8: =IF(INDIRECT("beschriftung!"&ADDRESS(beschriftung!$C$1*12+ROW(beschriftung!$A9)-1,COLUMN(beschriftung!AG$1)))="","",INDIRECT("beschriftung!"&ADDRESS(beschriftung!$C$1*12+ROW(beschriftung!$A9)-1,COLUMN(beschriftung!AG$1)))) -> thereof exp. of goods excluding valuables and merchanting | AO8: =IF(INDIRECT("beschriftung!"&ADDRESS(beschriftung!$C$1*12+ROW(beschriftung!$A9)-1,COLUMN(beschriftung!AO$1)))="","",INDIRECT("beschriftung!"&ADDRESS(beschriftung!$C$1*12+ROW(beschriftung!$A9)-1,COLUMN(beschriftung!AO$1)))) -> thereof imp. of goods excluding non-monetary gold | AQ8: =IF(INDIRECT("beschriftung!"&ADDRESS(beschriftung!$C$1*12+ROW(beschriftung!$A9)-1,COLUMN(beschriftung!AQ$1)))="","",INDIRECT("beschriftung!"&ADDRESS(beschriftung!$C$1*12+ROW(beschriftung!$A9)-1,COLUMN(beschriftung!AQ$1)))) -> thereof imp. of goods excluding valuables
C11: B.1*b | E11: P.3+P.5 | G11: P.3 | I11: S.14+S15 | K11: S.13 | M11: P.5 | O11: P.51 | Q11: P.5111c | S11: P.5111be | U11: P.52 | W11: P.53 | AA11: P.6 | AC11: P.61 | AI11: P.62 | AK11: P.7 | AM11: P.71 | AS11: P.72 | AW11: P.3+P.51
A12: 1980 | B12: 1 | C12: 55.579589 | E12: 59.665206 | G12: 57.335778 | I12: 59.000038 | K12: 49.584605 | M12: 64.784056 | O12: 74.434002 | Q12: 60.496021 | S12: 82.788122 | AA12: 88.302508 | AC12: 103.07198 | AE12: 89.049185 | AG12: 82.391942 | AI12: 58.827351 | AK12: 106.78932 | AM12: 114.59838 | AO12: 111.08211 | AQ12: 105.16951 | AS12: 78.203835 | AU12: 64.934359 | AW12: 61.86709 | AY12: 72.192621 | BA12: 80.899286 | BC12: 96.400308
A13: 1980 | B13: 2 | C13: 56.211847 | D13: 0.011375728 | E13: 60.119341 | F13: 0.0076113831 | G13: 57.79366 | H13: 0.007985978 | I13: 59.474471 | J13: 0.0080412445 | K13: 49.963562 | L13: 0.0076426375 | M13: 65.228078 | N13: 0.006853892 | O13: 75.401416 | P13: 0.01299694 | Q13: 62.013329 | R13: 0.025081119 | S13: 83.167017 | T13: 0.0045766831 | AA13: 87.445475 | AB13: -0.0097056466 | AC13: 101.67469 | AD13: -0.013556439 | AE13: 90.700558 | AF13: 0.018544503 | AG13: 83.93187 | AH13: 0.018690272 | AI13: 58.953034 | AJ13: 0.0021364628 | AK13: 105.00723 | AL13: -0.016687965 | AM13: 112.1251 | AN13: -0.021582188 | AO13: 111.49103 | AP13: 0.0036811973 | AQ13: 105.51713 | AR13: 0.0033053307 | AS13: 78.796956 | AT13: 0.0075842937 | AU13: 65.608151 | AV13: 0.010376505 | AW13: 62.456267 | AX13: 0.0095232691 | AY13: 73.123816 | AZ13: 0.012898765 | BA13: 82.392873 | BB13: 0.018462297 | BC13: 96.814937 | BD13: 0.0043011194
A14: 1980 | B14: 3 | C14: 56.770303 | D14: 0.0099348386 | E14: 60.564522 | F14: 0.0074049561 | G14: 58.387181 | H14: 0.01026966 | I14: 60.090128 | J14: 0.010351603 | K14: 50.451424 | L14: 0.009764354 | M14: 65.319589 | N14: 0.0014029276 | O14: 76.458033 | P14: 0.014013225 | Q14: 63.360955 | R14: 0.021731221 | S14: 83.866948 | T14: 0.0084159598 | AA14: 90.067185 | AB14: 0.029981085 | AC14: 105.72176 | AD14: 0.039804011 | AE14: 90.958936 | AF14: 0.0028486916 | AG14: 84.314255 | AH14: 0.0045559025 | AI14: 58.992919 | AJ14: 0.00067656453 | AK14: 107.55651 | AL14: 0.024277194 | AM14: 115.13664 | AN14: 0.026858766 | AO14: 111.42083 | AP14: -0.00062964305 | AQ14: 105.6384 | AR14: 0.0011492835 | AS14: 79.75708 | AT14: 0.012184786 | AU14: 66.221457 | AV14: 0.0093480169 | AW14: 63.1699 | AX14: 0.011426123 | AY14: 73.363531 | AZ14: 0.0032782004 | BA14: 82.774267 | BB14: 0.0046289638 | BC14: 97.170595 | BD14: 0.0036735892
A15: 1980 | B15: 4 | C15: 57.376728 | D15: 0.010682078 | E15: 61.579185 | F15: 0.016753423 | G15: 58.886882 | H15: 0.0085584005 | I15: 60.561278 | J15: 0.0078407278 | K15: 51.106467 | L15: 0.012983632 | M15: 67.571789 | N15: 0.034479705 | O15: 77.884552 | P15: 0.018657534 | Q15: 64.89401 | R15: 0.024195586 | S15: 85.087016 | T15: 0.014547664 | AA15: 91.104699 | AB15: 0.011519333 | AC15: 107.07669 | AD15: 0.012816069 | AE15: 91.841758 | AF15: 0.0097057273 | AG15: 85.759368 | AH15: 0.017139604 | AI15: 59.436298 | AJ15: 0.0075157894 | AK15: 110.18307 | AL15: 0.024420315 | AM15: 117.9831 | AN15: 0.024722434 | AO15: 114.56772 | AP15: 0.028243311 | AQ15: 109.41185 | AR15: 0.035720457 | AS15: 81.590719 | AT15: 0.0229903 | AU15: 67.031046 | AV15: 0.012225471 | AW15: 63.908914 | AX15: 0.011698841 | AY15: 74.373989 | AZ15: 0.013773297 | BA15: 84.187463 | BB15: 0.017072897 | BC15: 100.3471 | BD15: 0.032690025
A16: 1981 | B16: 1 | C16: 58.189226 | D16: 0.014160771 | E16: 62.920522 | F16: 0.021782309 | G16: 60.096435 | H16: 0.020540274 | I16: 61.831479 | J16: 0.020973814 | K16: 52.020615 | L16: 0.017887134 | M16: 69.23913 | N16: 0.0246751 | O16: 79.348602 | P16: 0.018797696 | Q16: 65.724034 | R16: 0.01279045 | S16: 87.076261 | T16: 0.023378952 | AA16: 89.411392 | AB16: -0.018586381 | AC16: 104.12048 | AD16: -0.02760837 | AE16: 92.299025 | AF16: 0.0049788547 | AG16: 87.165574 | AH16: 0.016397107 | AI16: 60.029016 | AJ16: 0.0099723288 | AK16: 109.77457 | AL16: -0.0037074728 | AM16: 116.93529 | AN16: -0.0088810261 | AO16: 117.61876 | AP16: 0.026630912 | AQ16: 113.39367 | AR16: 0.036392953 | AS16: 83.33193 | AT16: 0.021340805 | AU16: 68.272137 | AV16: 0.018515179 | AW16: 65.187231 | AX16: 0.020002167 | AY16: 75.431023 | AZ16: 0.014212425 | BA16: 85.56279 | BB16: 0.016336478 | BC16: 103.63869 | BD16: 0.03280202
A17: 1981 | B17: 2 | C17: 58.938103 | D17: 0.01286967 | E17: 63.968176 | F17: 0.016650444 | G17: 61.10584 | H17: 0.016796429 | I17: 62.834506 | J17: 0.016221944 | K17: 53.077718 | L17: 0.020320844 | M17: 70.414964 | N17: 0.016982221 | O17: 80.937761 | P17: 0.02002756 | Q17: 67.191862 | R17: 0.022333212 | S17: 88.668778 | T17: 0.018288766 | AA17: 88.136412 | AB17: -0.014259706 | AC17: 101.76712 | AD17: -0.022602274 | AE17: 90.514811 | AF17: -0.019330798 | AG17: 86.64917 | AH17: -0.0059244065 | AI17: 60.779603 | AJ17: 0.01250373 | AK17: 108.80844 | AL17: -0.0088010278 | AM17: 115.52445 | AN17: -0.012065073 | AO17: 116.69242 | AP17: -0.0078758459 | AQ17: 113.81161 | AR17: 0.0036857682 | AS17: 83.777299 | AT17: 0.0053445179 | AU17: 69.180721 | AV17: 0.013308271 | AW17: 66.347014 | AX17: 0.017791558 | AY17: 75.474022 | AZ17: 0.0005700382 | BA17: 85.086764 | BB17: -0.0055634633 | BC17: 104.05562 | BD17: 0.0040228716
A18: 1981 | B18: 3 | C18: 60.022826 | D18: 0.018404453 | E18: 64.721552 | F18: 0.011777346 | G18: 62.301309 | H18: 0.019563901 | I18: 64.049475 | J18: 0.019336029 | K18: 54.190023 | L18: 0.020956165 | M18: 70.027225 | N18: -0.0055064843 | O18: 82.161426 | P18: 0.0151186 | Q18: 68.127023 | R18: 0.013917767 | S18: 90.104878 | T18: 0.016196222 | AA18: 86.288844 | AB18: -0.020962593 | AC18: 98.437582 | AD18: -0.032717234 | AE18: 89.862907 | AF18: -0.0072021897 | AG18: 87.624287 | AH18: 0.011253631 | AI18: 62.128661 | AJ18: 0.022195909 | AK18: 105.31135 | AL18: -0.032139893 | AM18: 111.18726 | AN18: -0.03754351 | AO18: 116.04927 | AP18: -0.0055114607 | AQ18: 114.38972 | AR18: 0.0050794893 | AS18: 83.939396 | AT18: 0.001934854 | AU18: 70.379991 | AV18: 0.017335321 | AW18: 67.555081 | AX18: 0.018208324 | AY18: 76.614491 | AZ18: 0.015110756 | BA18: 86.056645 | BB18: 0.011398729 | BC18: 104.5137 | BD18: 0.0044022559
